2024-03-21 10:06:58,254 INFO: Microblog startup [in /home/vagrant/microblog/app/__init__.py:47]
2024-03-21 10:07:42,283 ERROR: Exception on /edit_profile [POST] [in /home/vagrant/microblog/venv/lib/python3.8/site-packages/flask/app.py:828]
Traceback (most recent call last):
  File "/home/vagrant/microblog/venv/lib/python3.8/site-packages/sqlalchemy/engine/base.py", line 1970, in _exec_single_context
    self.dialect.do_execute(
  File "/home/vagrant/microblog/venv/lib/python3.8/site-packages/sqlalchemy/engine/default.py", line 924, in do_execute
    cursor.execute(statement, parameters)
sqlite3.IntegrityError: UNIQUE constraint failed: user.username

The above exception was the direct cause of the following exception:

Traceback (most recent call last):
  File "/home/vagrant/microblog/venv/lib/python3.8/site-packages/flask/app.py", line 1463, in wsgi_app
    response = self.full_dispatch_request()
  File "/home/vagrant/microblog/venv/lib/python3.8/site-packages/flask/app.py", line 872, in full_dispatch_request
    rv = self.handle_user_exception(e)
  File "/home/vagrant/microblog/venv/lib/python3.8/site-packages/flask/app.py", line 870, in full_dispatch_request
    rv = self.dispatch_request()
  File "/home/vagrant/microblog/venv/lib/python3.8/site-packages/flask/app.py", line 855, in dispatch_request
    return self.ensure_sync(self.view_functions[rule.endpoint])(**view_args)  # type: ignore[no-any-return]
  File "/home/vagrant/microblog/app/routes.py", line 104, in edit_profile
    db.session.commit()
  File "/home/vagrant/microblog/venv/lib/python3.8/site-packages/sqlalchemy/orm/scoping.py", line 597, in commit
    return self._proxied.commit()
  File "/home/vagrant/microblog/venv/lib/python3.8/site-packages/sqlalchemy/orm/session.py", line 1972, in commit
    trans.commit(_to_root=True)
  File "<string>", line 2, in commit
  File "/home/vagrant/microblog/venv/lib/python3.8/site-packages/sqlalchemy/orm/state_changes.py", line 139, in _go
    ret_value = fn(self, *arg, **kw)
  File "/home/vagrant/microblog/venv/lib/python3.8/site-packages/sqlalchemy/orm/session.py", line 1257, in commit
    self._prepare_impl()
  File "<string>", line 2, in _prepare_impl
  File "/home/vagrant/microblog/venv/lib/python3.8/site-packages/sqlalchemy/orm/state_changes.py", line 139, in _go
    ret_value = fn(self, *arg, **kw)
  File "/home/vagrant/microblog/venv/lib/python3.8/site-packages/sqlalchemy/orm/session.py", line 1232, in _prepare_impl
    self.session.flush()
  File "/home/vagrant/microblog/venv/lib/python3.8/site-packages/sqlalchemy/orm/session.py", line 4296, in flush
    self._flush(objects)
  File "/home/vagrant/microblog/venv/lib/python3.8/site-packages/sqlalchemy/orm/session.py", line 4432, in _flush
    transaction.rollback(_capture_exception=True)
  File "/home/vagrant/microblog/venv/lib/python3.8/site-packages/sqlalchemy/util/langhelpers.py", line 146, in __exit__
    raise exc_value.with_traceback(exc_tb)
  File "/home/vagrant/microblog/venv/lib/python3.8/site-packages/sqlalchemy/orm/session.py", line 4392, in _flush
    flush_context.execute()
  File "/home/vagrant/microblog/venv/lib/python3.8/site-packages/sqlalchemy/orm/unitofwork.py", line 466, in execute
    rec.execute(self)
  File "/home/vagrant/microblog/venv/lib/python3.8/site-packages/sqlalchemy/orm/unitofwork.py", line 642, in execute
    util.preloaded.orm_persistence.save_obj(
  File "/home/vagrant/microblog/venv/lib/python3.8/site-packages/sqlalchemy/orm/persistence.py", line 85, in save_obj
    _emit_update_statements(
  File "/home/vagrant/microblog/venv/lib/python3.8/site-packages/sqlalchemy/orm/persistence.py", line 912, in _emit_update_statements
    c = connection.execute(
  File "/home/vagrant/microblog/venv/lib/python3.8/site-packages/sqlalchemy/engine/base.py", line 1421, in execute
    return meth(
  File "/home/vagrant/microblog/venv/lib/python3.8/site-packages/sqlalchemy/sql/elements.py", line 514, in _execute_on_connection
    return connection._execute_clauseelement(
  File "/home/vagrant/microblog/venv/lib/python3.8/site-packages/sqlalchemy/engine/base.py", line 1643, in _execute_clauseelement
    ret = self._execute_context(
  File "/home/vagrant/microblog/venv/lib/python3.8/site-packages/sqlalchemy/engine/base.py", line 1849, in _execute_context
    return self._exec_single_context(
  File "/home/vagrant/microblog/venv/lib/python3.8/site-packages/sqlalchemy/engine/base.py", line 1989, in _exec_single_context
    self._handle_dbapi_exception(
  File "/home/vagrant/microblog/venv/lib/python3.8/site-packages/sqlalchemy/engine/base.py", line 2356, in _handle_dbapi_exception
    raise sqlalchemy_exception.with_traceback(exc_info[2]) from e
  File "/home/vagrant/microblog/venv/lib/python3.8/site-packages/sqlalchemy/engine/base.py", line 1970, in _exec_single_context
    self.dialect.do_execute(
  File "/home/vagrant/microblog/venv/lib/python3.8/site-packages/sqlalchemy/engine/default.py", line 924, in do_execute
    cursor.execute(statement, parameters)
sqlalchemy.exc.IntegrityError: (sqlite3.IntegrityError) UNIQUE constraint failed: user.username
[SQL: UPDATE user SET username=?, about_me=? WHERE user.id = ?]
[parameters: ('Ifeoluwa', "I'm Gabriel, a software developer with two years of experience and a DevOps engineer", 4)]
(Background on this error at: https://sqlalche.me/e/20/gkpj)
2024-03-21 10:26:56,911 INFO: Microblog startup [in /home/vagrant/microblog/app/__init__.py:47]
2024-03-21 10:27:41,695 INFO: Microblog startup [in /home/vagrant/microblog/app/__init__.py:47]
2024-03-21 10:50:54,507 INFO: Microblog startup [in /home/vagrant/microblog/app/__init__.py:47]
